Workbook

Sheet Read me
A1: Revert Guide: content verification tracker
A2: One workbook for the review team. Every piece of site text that a scholar, mentor or professional should verify is listed on the 'Review rows' sheet, one text section per row, with the English and the Bengali text side by side, the kind of review it needs, the sources it cites, and yellow columns for your verdict and comments.
A3: Generated | B3: 2026-09-26 from the content files in the repository (last commit da3ea47). Re-run scripts/verification-tracker/build.py to refresh it after content changes, passing --previous with the filled-in copy so the yellow columns are carried over (rows are matched on 'Item key' plus 'JSON location', items on 'Item key', sources and masjids on their ids).
A4: Contents | B4: 2057 text rows across 689 items on 'Review rows'; 1506 sources on 'Sources'; 459 masjid records on 'Masjids'; 58 findings on 'Site team notes'. The counts on 'Items' and 'Summary' are formulas and calculate when the file opens (Excel may ask to save on close because of this).
A5: Colour key | B5: Dark header = generated column (read only). Gold header and pale yellow cells = for the review team to fill in. Grey cells = formulas.
A7: How to use it
A8: • | B8: Open 'Review rows'. Use the filters in the header row to pick your part: filter 'Area' (for example FAQ, Topic, Roadmap step), 'Suggested reviewer' (Scholar, Mentor, Mental health professional, Legal professional, Medical professional) or 'Review needed'. Several values are joined with '; ' in one cell, so type a word into the filter's search box (for example 'Scholar' or 'Medical') rather than picking exact combinations. Most rows are High priority because most of the site is still unreviewed; filter by area or review type to carve out a manageable slice.
A9: • | B9: Read the English text. If you review Bengali, read the Bengali text next to it and judge both the meaning and the translation.
A10: • | B10: Check the claims against 'Sources used' (the ids point to the 'Sources' sheet, which has every link) and against 'Key points to check'.
A11: • | B11: Fill in the yellow columns only: 'English verdict' (Approved, Needs changes, Rejected, Unsure), 'English reviewer' (your name), 'English comments' (what to change and why; quote the exact words). Bengali reviewers use the three Bengali columns the same way.
A12: • | B12: Set 'Done' to Yes once the row is settled in both languages. The 'Items' and 'Summary' sheets count progress automatically.
A13: • | B13: Grey and white columns are generated from the site's content files: do not edit them. If a text is wrong, say so in the comments and the site team will fix the content file named in 'JSON location'.
A14: • | B14: 'Sources' and 'Masjids' are separate sheets with their own verdict columns: sources need a citation check (collection, number, grading, working link); masjids need a directory check (mainstream Sunni, details current).
A15: • | B15: 'Site team notes' lists cross-cutting findings from the preparation of this workbook (duplicate entries, missing source ids, naming-rule slips, facts to confirm, code-defined text). They are for the site team and a scholar where marked; each has a status column.
A16: • | B16: Not covered here: the 99 names of Allah page, whose names and English meanings are fetched from the AlAdhan API at run time rather than stored in the site; the live prayer-times data; and short interface labels (buttons, menu items, form labels). Everything else that a visitor can read is on one of the sheets.
A18: What the generated columns mean
A19: Priority | B19: High: unreviewed text that carries rulings, belief, suicide or self-harm, safety, legal, financial, medical or mental-health guidance. Medium: unreviewed practical text, or source-checked text that still makes religious claims. Low: everything else. A row that mentions suicide, self-harm or a crisis line is always High, whatever its item's priority.
A20: Review needed | B20: The kinds of verification the row needs (see the list below). A row can need several.
A21: Suggested reviewer | B21: Who should look first. Scholars for religious content, mentors for lived-experience and practical guidance, professionals for clinical, legal or medical claims.
A22: Current status (site) | B22: The reviewStatus recorded in the content file today: 'review-needed' = Touches rulings, mental health, safety, legal, financial or sensitive family matters and still needs a qualified reviewer. 'source-checked' = The cited sources were verified against their links; the content itself still awaits a reviewer. 'draft' = Not yet checked at all. 'approved' = A qualified reviewer approved it. 'not tracked' = This part of the site has no review status field yet (stages, glossary entries, site page text). 'not tracked' covers the stages, the glossary, the site page text, the Ramadan planning sections, the resource collections, the seasonal calendar, the source categories and the illustrations.
A23: Bengali status | B23: Translated: Bengali text exists. Missing: no Bengali text for this section (the illustration rows are Missing by design: the images carry English text in every language). Same as English / Not translated: the Bengali file still carries the English words. Not needed: the text is Arabic, a link or a number and needs no translation.
A24: Sources used | B24: The source ids the site cites for this text, with title and organisation, one per line. The column does not wrap, so click the cell (or read the formula bar) to see the whole list, and look the id up on the 'Sources' sheet for the link and the note on what it supports. The 'Items' sheet repeats the list with links.
A25: Key points to check | B25: A machine-generated reading list of the specific claims, citations, numbers and names in the item. It is a pointer, not a verdict. It is shown on the first row of each item (and on the 'Items' sheet), so look there when an item has several rows.
A26: Pre-check flags | B26: Machine-generated warnings about a possible breach of the site's own rules (for example suicide-safe wording, 911 before 9-8-8, a missing source), shown on the first row of each item and on 'Items'. Please confirm or dismiss them in your comments.
A27: Sources (n) | B27: How many source ids the row carries. For tool pages and the Ramadan planning sections, sections without their own ids show the page's source list, which the site defines in the page code; every topic row repeats the topic's whole list because topics cite sources at page level.
A28: Page URL / JSON location | B28: Where the text appears on the site (with an anchor to the section where one exists) and where it lives in the content files, for the site team. 'Content ID' and 'Item key' identify the item; 'Item key' plus 'JSON location' is the stable key for merging a filled-in copy into a rebuilt workbook.
A29: Date done | B29: The date the row was settled, in whatever format you like; it is not counted.
A30: Items sheet | B30: One row per item with formulas counting its rows. Its three yellow columns are for assigning a reviewer to the whole item, an item-level verdict, and notes.
A32: Review types
A33: Fiqh ruling | B33: What is obligatory, permitted or forbidden, and how worship is performed.
A34: Aqidah (belief) | B34: Statements about Allah, prophets, revelation, the afterlife and creed.
A35: Quran or hadith citation | B35: A verse or hadith is quoted, paraphrased or cited: check reference, wording and grading.
A36: Seerah or history | B36: Claims about the Prophet's life, the companions or Islamic history.
A37: Arabic text or transliteration | B37: Arabic script, transliteration or translation of a phrase, dua or term.
A38: Mental health | B38: Emotional wellbeing, anxiety, depression, therapy, grief, waswas.
A39: Suicide-safe language | B39: Suicide or self-harm is mentioned: check wording and that 911 comes before 9-8-8.
A40: Safety or abuse | B40: Domestic violence, coercion, personal safety, emergencies.
A41: Legal (Canada) | B41: Law, rights, wills, marriage law, immigration, workplace or school accommodation.
A42: Financial (zakat, riba, money) | B42: Zakat rules or numbers, interest, mortgages, banking, debt.
A43: Medical or health | B43: Menstruation, illness and fasting, medication, pregnancy, disability, hygiene.
...

Sheet Summary
A1: Revert Guide content verification: progress summary
A2: All numbers are formulas over the other sheets and update as the team fills in the yellow columns.
A4: Area | B4: Items | C4: Text rows | D4: High priority rows | E4: Rows done | F4: % done | G4: EN approved | H4: BN approved
A5: Roadmap stage | B5: =COUNTIF(Items!$B$2:$B$690,$A5) -> 6 | C5: =COUNTIF('Review rows'!$B$2:$B$2058,$A5) -> 66 | D5: =COUNTIFS('Review rows'!$B$2:$B$2058,$A5,'Review rows'!$H$2:$H$2058,"High") -> 24 | E5: =COUNTIFS('Review rows'!$B$2:$B$2058,$A5,'Review rows'!$V$2:$V$2058,"Yes") -> 0 | F5: =IF(C5=0,0,E5/C5) -> 0 | G5: =COUNTIFS('Review rows'!$B$2:$B$2058,$A5,'Review rows'!$P$2:$P$2058,"Approved") -> 0 | H5: =COUNTIFS('Review rows'!$B$2:$B$2058,$A5,'Review rows'!$S$2:$S$2058,"Approved") -> 0
A6: Roadmap step | B6: =COUNTIF(Items!$B$2:$B$690,$A6) -> 20 | C6: =COUNTIF('Review rows'!$B$2:$B$2058,$A6) -> 286 | D6: =COUNTIFS('Review rows'!$B$2:$B$2058,$A6,'Review rows'!$H$2:$H$2058,"High") -> 193 | E6: =COUNTIFS('Review rows'!$B$2:$B$2058,$A6,'Review rows'!$V$2:$V$2058,"Yes") -> 0 | F6: =IF(C6=0,0,E6/C6) -> 0 | G6: =COUNTIFS('Review rows'!$B$2:$B$2058,$A6,'Review rows'!$P$2:$P$2058,"Approved") -> 0 | H6: =COUNTIFS('Review rows'!$B$2:$B$2058,$A6,'Review rows'!$S$2:$S$2058,"Approved") -> 0
A7: Topic | B7: =COUNTIF(Items!$B$2:$B$690,$A7) -> 22 | C7: =COUNTIF('Review rows'!$B$2:$B$2058,$A7) -> 228 | D7: =COUNTIFS('Review rows'!$B$2:$B$2058,$A7,'Review rows'!$H$2:$H$2058,"High") -> 221 | E7: =COUNTIFS('Review rows'!$B$2:$B$2058,$A7,'Review rows'!$V$2:$V$2058,"Yes") -> 0 | F7: =IF(C7=0,0,E7/C7) -> 0 | G7: =COUNTIFS('Review rows'!$B$2:$B$2058,$A7,'Review rows'!$P$2:$P$2058,"Approved") -> 0 | H7: =COUNTIFS('Review rows'!$B$2:$B$2058,$A7,'Review rows'!$S$2:$S$2058,"Approved") -> 0
A8: Life guide | B8: =COUNTIF(Items!$B$2:$B$690,$A8) -> 22 | C8: =COUNTIF('Review rows'!$B$2:$B$2058,$A8) -> 383 | D8: =COUNTIFS('Review rows'!$B$2:$B$2058,$A8,'Review rows'!$H$2:$H$2058,"High") -> 383 | E8: =COUNTIFS('Review rows'!$B$2:$B$2058,$A8,'Review rows'!$V$2:$V$2058,"Yes") -> 0 | F8: =IF(C8=0,0,E8/C8) -> 0 | G8: =COUNTIFS('Review rows'!$B$2:$B$2058,$A8,'Review rows'!$P$2:$P$2058,"Approved") -> 0 | H8: =COUNTIFS('Review rows'!$B$2:$B$2058,$A8,'Review rows'!$S$2:$S$2058,"Approved") -> 0
A9: Seasonal guide | B9: =COUNTIF(Items!$B$2:$B$690,$A9) -> 8 | C9: =COUNTIF('Review rows'!$B$2:$B$2058,$A9) -> 112 | D9: =COUNTIFS('Review rows'!$B$2:$B$2058,$A9,'Review rows'!$H$2:$H$2058,"High") -> 87 | E9: =COUNTIFS('Review rows'!$B$2:$B$2058,$A9,'Review rows'!$V$2:$V$2058,"Yes") -> 0 | F9: =IF(C9=0,0,E9/C9) -> 0 | G9: =COUNTIFS('Review rows'!$B$2:$B$2058,$A9,'Review rows'!$P$2:$P$2058,"Approved") -> 0 | H9: =COUNTIFS('Review rows'!$B$2:$B$2058,$A9,'Review rows'!$S$2:$S$2058,"Approved") -> 0
A10: FAQ | B10: =COUNTIF(Items!$B$2:$B$690,$A10) -> 222 | C10: =COUNTIF('Review rows'!$B$2:$B$2058,$A10) -> 222 | D10: =COUNTIFS('Review rows'!$B$2:$B$2058,$A10,'Review rows'!$H$2:$H$2058,"High") -> 163 | E10: =COUNTIFS('Review rows'!$B$2:$B$2058,$A10,'Review rows'!$V$2:$V$2058,"Yes") -> 0 | F10: =IF(C10=0,0,E10/C10) -> 0 | G10: =COUNTIFS('Review rows'!$B$2:$B$2058,$A10,'Review rows'!$P$2:$P$2058,"Approved") -> 0 | H10: =COUNTIFS('Review rows'!$B$2:$B$2058,$A10,'Review rows'!$S$2:$S$2058,"Approved") -> 0
A11: Glossary | B11: =COUNTIF(Items!$B$2:$B$690,$A11) -> 188 | C11: =COUNTIF('Review rows'!$B$2:$B$2058,$A11) -> 188 | D11: =COUNTIFS('Review rows'!$B$2:$B$2058,$A11,'Review rows'!$H$2:$H$2058,"High") -> 85 | E11: =COUNTIFS('Review rows'!$B$2:$B$2058,$A11,'Review rows'!$V$2:$V$2058,"Yes") -> 0 | F11: =IF(C11=0,0,E11/C11) -> 0 | G11: =COUNTIFS('Review rows'!$B$2:$B$2058,$A11,'Review rows'!$P$2:$P$2058,"Approved") -> 0 | H11: =COUNTIFS('Review rows'!$B$2:$B$2058,$A11,'Review rows'!$S$2:$S$2058,"Approved") -> 0
A12: Tool page | B12: =COUNTIF(Items!$B$2:$B$690,$A12) -> 4 | C12: =COUNTIF('Review rows'!$B$2:$B$2058,$A12) -> 166 | D12: =COUNTIFS('Review rows'!$B$2:$B$2058,$A12,'Review rows'!$H$2:$H$2058,"High") -> 166 | E12: =COUNTIFS('Review rows'!$B$2:$B$2058,$A12,'Review rows'!$V$2:$V$2058,"Yes") -> 0 | F12: =IF(C12=0,0,E12/C12) -> 0 | G12: =COUNTIFS('Review rows'!$B$2:$B$2058,$A12,'Review rows'!$P$2:$P$2058,"Approved") -> 0 | H12: =COUNTIFS('Review rows'!$B$2:$B$2058,$A12,'Review rows'!$S$2:$S$2058,"Approved") -> 0
A13: Tool page text | B13: =COUNTIF(Items!$B$2:$B$690,$A13) -> 44 | C13: =COUNTIF('Review rows'!$B$2:$B$2058,$A13) -> 49 | D13: =COUNTIFS('Review rows'!$B$2:$B$2058,$A13,'Review rows'!$H$2:$H$2058,"High") -> 21 | E13: =COUNTIFS('Review rows'!$B$2:$B$2058,$A13,'Review rows'!$V$2:$V$2058,"Yes") -> 0 | F13: =IF(C13=0,0,E13/C13) -> 0 | G13: =COUNTIFS('Review rows'!$B$2:$B$2058,$A13,'Review rows'!$P$2:$P$2058,"Approved") -> 0 | H13: =COUNTIFS('Review rows'!$B$2:$B$2058,$A13,'Review rows'!$S$2:$S$2058,"Approved") -> 0
A14: Ramadan guide page | B14: =COUNTIF(Items!$B$2:$B$690,$A14) -> 13 | C14: =COUNTIF('Review rows'!$B$2:$B$2058,$A14) -> 25 | D14: =COUNTIFS('Review rows'!$B$2:$B$2058,$A14,'Review rows'!$H$2:$H$2058,"High") -> 25 | E14: =COUNTIFS('Review rows'!$B$2:$B$2058,$A14,'Review rows'!$V$2:$V$2058,"Yes") -> 0 | F14: =IF(C14=0,0,E14/C14) -> 0 | G14: =COUNTIFS('Review rows'!$B$2:$B$2058,$A14,'Review rows'!$P$2:$P$2058,"Approved") -> 0 | H14: =COUNTIFS('Review rows'!$B$2:$B$2058,$A14,'Review rows'!$S$2:$S$2058,"Approved") -> 0
A15: Mental health page | B15: =COUNTIF(Items!$B$2:$B$690,$A15) -> 8 | C15: =COUNTIF('Review rows'!$B$2:$B$2058,$A15) -> 40 | D15: =COUNTIFS('Review rows'!$B$2:$B$2058,$A15,'Review rows'!$H$2:$H$2058,"High") -> 39 | E15: =COUNTIFS('Review rows'!$B$2:$B$2058,$A15,'Review rows'!$V$2:$V$2058,"Yes") -> 0 | F15: =IF(C15=0,0,E15/C15) -> 0 | G15: =COUNTIFS('Review rows'!$B$2:$B$2058,$A15,'Review rows'!$P$2:$P$2058,"Approved") -> 0 | H15: =COUNTIFS('Review rows'!$B$2:$B$2058,$A15,'Review rows'!$S$2:$S$2058,"Approved") -> 0
A16: Help & community pages | B16: =COUNTIF(Items!$B$2:$B$690,$A16) -> 24 | C16: =COUNTIF('Review rows'!$B$2:$B$2058,$A16) -> 24 | D16: =COUNTIFS('Review rows'!$B$2:$B$2058,$A16,'Review rows'!$H$2:$H$2058,"High") -> 11 | E16: =COUNTIFS('Review rows'!$B$2:$B$2058,$A16,'Review rows'!$V$2:$V$2058,"Yes") -> 0 | F16: =IF(C16=0,0,E16/C16) -> 0 | G16: =COUNTIFS('Review rows'!$B$2:$B$2058,$A16,'Review rows'!$P$2:$P$2058,"Approved") -> 0 | H16: =COUNTIFS('Review rows'!$B$2:$B$2058,$A16,'Review rows'!$S$2:$S$2058,"Approved") -> 0
... A24: Illustration text (SVG) | B24: =COUNTIF(Items!$B$2:$B$690,$A24) -> 10 | C24: =COUNTIF('Review rows'!$B$2:$B$2058,$A24) -> 20 | D24: =COUNTIFS('Review rows'!$B$2:$B$2058,$A24,'Review rows'!$H$2:$H$2058,"High") -> 20 | E24: =COUNTIFS('Review rows'!$B$2:$B$2058,$A24,'Review rows'!$V$2:$V$2058,"Yes") -> 0 | F24: =IF(C24=0,0,E24/C24) -> 0 | G24: =COUNTIFS('Review rows'!$B$2:$B$2058,$A24,'Review rows'!$P$2:$P$2058,"Approved") -> 0 | H24: =COUNTIFS('Review rows'!$B$2:$B$2058,$A24,'Review rows'!$S$2:$S$2058,"Approved") -> 0
A25: Total | B25: =SUM(B5:B24) -> 689 | C25: =SUM(C5:C24) -> 2057 | D25: =SUM(D5:D24) -> 1477 | E25: =SUM(E5:E24) -> 0 | F25: =IF(C25=0,0,E25/C25) -> 0 | G25: =SUM(G5:G24) -> 0 | H25: =SUM(H5:H24) -> 0
A27: Review type | B27: Text rows | C27: Rows done | D27: % done
A28: Fiqh ruling | B28: =COUNTIF('Review rows'!$I$2:$I$2058,"*"&$A28&"*") -> 1282 | C28: =COUNTIFS('Review rows'!$I$2:$I$2058,"*"&$A28&"*",'Review rows'!$V$2:$V$2058,"Yes") -> 0 | D28: =IF(B28=0,0,C28/B28) -> 0
A29: Aqidah (belief) | B29: =COUNTIF('Review rows'!$I$2:$I$2058,"*"&$A29&"*") -> 362 | C29: =COUNTIFS('Review rows'!$I$2:$I$2058,"*"&$A29&"*",'Review rows'!$V$2:$V$2058,"Yes") -> 0 | D29: =IF(B29=0,0,C29/B29) -> 0
A30: Quran or hadith citation | B30: =COUNTIF('Review rows'!$I$2:$I$2058,"*"&$A30&"*") -> 422 | C30: =COUNTIFS('Review rows'!$I$2:$I$2058,"*"&$A30&"*",'Review rows'!$V$2:$V$2058,"Yes") -> 0 | D30: =IF(B30=0,0,C30/B30) -> 0
A31: Seerah or history | B31: =COUNTIF('Review rows'!$I$2:$I$2058,"*"&$A31&"*") -> 107 | C31: =COUNTIFS('Review rows'!$I$2:$I$2058,"*"&$A31&"*",'Review rows'!$V$2:$V$2058,"Yes") -> 0 | D31: =IF(B31=0,0,C31/B31) -> 0
A32: Arabic text or transliteration | B32: =COUNTIF('Review rows'!$I$2:$I$2058,"*"&$A32&"*") -> 274 | C32: =COUNTIFS('Review rows'!$I$2:$I$2058,"*"&$A32&"*",'Review rows'!$V$2:$V$2058,"Yes") -> 0 | D32: =IF(B32=0,0,C32/B32) -> 0
A33: Mental health | B33: =COUNTIF('Review rows'!$I$2:$I$2058,"*"&$A33&"*") -> 593 | C33: =COUNTIFS('Review rows'!$I$2:$I$2058,"*"&$A33&"*",'Review rows'!$V$2:$V$2058,"Yes") -> 0 | D33: =IF(B33=0,0,C33/B33) -> 0
A34: Suicide-safe language | B34: =COUNTIF('Review rows'!$I$2:$I$2058,"*"&$A34&"*") -> 51 | C34: =COUNTIFS('Review rows'!$I$2:$I$2058,"*"&$A34&"*",'Review rows'!$V$2:$V$2058,"Yes") -> 0 | D34: =IF(B34=0,0,C34/B34) -> 0
A35: Safety or abuse | B35: =COUNTIF('Review rows'!$I$2:$I$2058,"*"&$A35&"*") -> 571 | C35: =COUNTIFS('Review rows'!$I$2:$I$2058,"*"&$A35&"*",'Review rows'!$V$2:$V$2058,"Yes") -> 0 | D35: =IF(B35=0,0,C35/B35) -> 0
A36: Legal (Canada) | B36: =COUNTIF('Review rows'!$I$2:$I$2058,"*"&$A36&"*") -> 379 | C36: =COUNTIFS('Review rows'!$I$2:$I$2058,"*"&$A36&"*",'Review rows'!$V$2:$V$2058,"Yes") -> 0 | D36: =IF(B36=0,0,C36/B36) -> 0
A37: Financial (zakat, riba, money) | B37: =COUNTIF('Review rows'!$I$2:$I$2058,"*"&$A37&"*") -> 256 | C37: =COUNTIFS('Review rows'!$I$2:$I$2058,"*"&$A37&"*",'Review rows'!$V$2:$V$2058,"Yes") -> 0 | D37: =IF(B37=0,0,C37/B37) -> 0
A38: Medical or health | B38: =COUNTIF('Review rows'!$I$2:$I$2058,"*"&$A38&"*") -> 339 | C38: =COUNTIFS('Review rows'!$I$2:$I$2058,"*"&$A38&"*",'Review rows'!$V$2:$V$2058,"Yes") -> 0 | D38: =IF(B38=0,0,C38/B38) -> 0
A39: Family, marriage or intimacy | B39: =COUNTIF('Review rows'!$I$2:$I$2058,"*"&$A39&"*") -> 458 | C39: =COUNTIFS('Review rows'!$I$2:$I$2058,"*"&$A39&"*",'Review rows'!$V$2:$V$2058,"Yes") -> 0 | D39: =IF(B39=0,0,C39/B39) -> 0
... A43: Site policy or legal notice | B43: =COUNTIF('Review rows'!$I$2:$I$2058,"*"&$A43&"*") -> 137 | C43: =COUNTIFS('Review rows'!$I$2:$I$2058,"*"&$A43&"*",'Review rows'!$V$2:$V$2058,"Yes") -> 0 | D43: =IF(B43=0,0,C43/B43) -> 0
A45: Suggested reviewer | B45: Text rows | C45: Rows done | D45: % done
A46: Scholar | B46: =COUNTIF('Review rows'!$J$2:$J$2058,"*"&$A46&"*") -> 1789 | C46: =COUNTIFS('Review rows'!$J$2:$J$2058,"*"&$A46&"*",'Review rows'!$V$2:$V$2058,"Yes") -> 0 | D46: =IF(B46=0,0,C46/B46) -> 0
A47: Mentor | B47: =COUNTIF('Review rows'!$J$2:$J$2058,"*"&$A47&"*") -> 1334 | C47: =COUNTIFS('Review rows'!$J$2:$J$2058,"*"&$A47&"*",'Review rows'!$V$2:$V$2058,"Yes") -> 0 | D47: =IF(B47=0,0,C47/B47) -> 0
A48: Mental health professional | B48: =COUNTIF('Review rows'!$J$2:$J$2058,"*"&$A48&"*") -> 603 | C48: =COUNTIFS('Review rows'!$J$2:$J$2058,"*"&$A48&"*",'Review rows'!$V$2:$V$2058,"Yes") -> 0 | D48: =IF(B48=0,0,C48/B48) -> 0
A49: Legal professional | B49: =COUNTIF('Review rows'!$J$2:$J$2058,"*"&$A49&"*") -> 405 | C49: =COUNTIFS('Review rows'!$J$2:$J$2058,"*"&$A49&"*",'Review rows'!$V$2:$V$2058,"Yes") -> 0 | D49: =IF(B49=0,0,C49/B49) -> 0
A50: Medical professional | B50: =COUNTIF('Review rows'!$J$2:$J$2058,"*"&$A50&"*") -> 339 | C50: =COUNTIFS('Review rows'!$J$2:$J$2058,"*"&$A50&"*",'Review rows'!$V$2:$V$2058,"Yes") -> 0 | D50: =IF(B50=0,0,C50/B50) -> 0
A52: Priority | B52: Text rows | C52: Rows done | D52: % done
A53: High | B53: =COUNTIF('Review rows'!$H$2:$H$2058,$A53) -> 1477 | C53: =COUNTIFS('Review rows'!$H$2:$H$2058,$A53,'Review rows'!$V$2:$V$2058,"Yes") -> 0 | D53: =IF(B53=0,0,C53/B53) -> 0
A54: Medium | B54: =COUNTIF('Review rows'!$H$2:$H$2058,$A54) -> 558 | C54: =COUNTIFS('Review rows'!$H$2:$H$2058,$A54,'Review rows'!$V$2:$V$2058,"Yes") -> 0 | D54: =IF(B54=0,0,C54/B54) -> 0
...

Sheet Review rows
A1: Row ID | B1: Area | C1: Item | D1: Section | E1: English text | F1: Bengali text (বাংলা) | G1: Bengali status | H1: Priority | I1: Review needed | J1: Suggested reviewer | K1: Current status (site) | L1: Sources (n) | M1: Sources used (id — title) | N1: Key points to check | O1: Pre-check flags | P1: English verdict | Q1: English reviewer | R1: English comments | S1: Bengali verdict | T1: Bengali reviewer | U1: Bengali comments | V1: Done | W1: Date done | X1: Page URL | Y1: Content ID | Z1: JSON location | AA1: Item key
A2: R0001 | B2: Roadmap stage | C2: Faith and a fresh start | D2: Title, subtitle and description | E2: Faith and a fresh start Day 0-1 Duration: 1-2 days The first day or two is about protecting what just happened. Keep your faith close, stay calm, make Ghusl, and pick one or two next steps you trust. You do not have to rebuild your whole life by tomorrow. | F2: ঈমান আর নতুন শুরু দিন 0-1 Duration: 1-2 দিন প্রথম এক-দুই দিন হলো সদ্য যা ঘটেছে তা রক্ষা করার সময়। ঈমানকে কাছে রাখুন, শান্ত থাকুন, গোসল করুন, আর বিশ্বাস করেন এমন এক বা দুটি পরের ধাপ বেছে নিন। কালকের মধ্যে পুরো জীবন নতুন করে গড়তে হবে না। | G2: Translated | H2: High | I2: Fiqh ruling; Safety or abuse; External resource or teacher; Tone and pastoral wording | J2: Scholar; Mentor | K2: not tracked | L2: 3 | M2: new-muslim-academy — New Muslim Academy (New Muslim Academy) whyislam — WhyIslam (Islamic Circle of North America) new-muslim-guide — New Muslim Guide (New Muslim Guide) | N2: • Says changing your name is not required (scholars usually add: unless the name's meaning conflicts with Islam). • Says make Ghusl 'when you feel ready'; the wudu-ghusl tool says it is required before prayer if you were in a state needing ghusl. • Recommends Mustafa Umar's 'Welcome to Islam', described as a free 32-page guide on his website; confirm page count and free access. • Ask-for-help triggers include not feeling safe telling family and needing a witness or certificate; no contacts are named. | X2: https://www.revertguide.com/en/roadmap/day-0-1 | Y2: day-0-1 | Z2: locales/en/stages.json › [id=day-0-1].title/subtitle/description | AA2: stage:day-0-1
A3: R0002 | B3: Roadmap stage | C3: Faith and a fresh start | D3: Main goal | E3: Know what your Shahada means, get through the first 24 hours gently, and make Ghusl when you feel ready. | F3: আপনার শাহাদার অর্থ জানা, প্রথম 24 ঘণ্টা নরমভাবে পার করা, আর প্রস্তুত হলে গোসল করা। | G3: Translated | H3: High | I3: Fiqh ruling; Safety or abuse; External resource or teacher; Tone and pastoral wording | J3: Scholar; Mentor | K3: not tracked | L3: 3 | M3: new-muslim-academy — New Muslim Academy (New Muslim Academy) whyislam — WhyIslam (Islamic Circle of North America) new-muslim-guide — New Muslim Guide (New Muslim Guide) | X3: https://www.revertguide.com/en/roadmap/day-0-1#overview-heading | Y3: day-0-1 | Z3: locales/en/stages.json › [id=day-0-1].mainGoal | AA3: stage:day-0-1
A4: R0003 | B4: Roadmap stage | C4: Faith and a fresh start | D4: Success looks like | E4: You know you are Muslim, you have one simple next step, and you are not forcing yourself to learn all of it at once. | F4: আপনি জানেন আপনি মুসলিম, আপনার সামনে একটি সহজ পরের ধাপ আছে, আর একসাথে সব শেখার জন্য নিজের ওপর জোর খাটাচ্ছেন না। | G4: Translated | H4: High | I4: Fiqh ruling; Safety or abuse; External resource or teacher; Tone and pastoral wording | J4: Scholar; Mentor | K4: not tracked | L4: 3 | M4: new-muslim-academy — New Muslim Academy (New Muslim Academy) whyislam — WhyIslam (Islamic Circle of North America) new-muslim-guide — New Muslim Guide (New Muslim Guide) | X4: https://www.revertguide.com/en/roadmap/day-0-1#overview-heading | Y4: day-0-1 | Z4: locales/en/stages.json › [id=day-0-1].success | AA4: stage:day-0-1
A5: R0004 | B5: Roadmap stage | C5: Faith and a fresh start | D5: Don't worry about | E5: • Long prayers can wait. Nobody expects you to have them memorized. • You do not have to change your name. It is not required. • You do not have to announce anything to anyone yet. • You will not know every rule for a long time, and that is how it goes for everyone. | F5: • লম্বা নামাজ অপেক্ষা করতে পারে। কেউ আশা করে না সেগুলো আপনার মুখস্থ। • নাম বদলাতে হবে না। এটি আবশ্যক নয়। • এখনই কাউকে কিছু ঘোষণা দিতে হবে না। • অনেক দিন পর্যন্ত আপনি সব নিয়ম জানবেন না, আর সবার ক্ষেত্রেই এমন হয়। | G5: Translated | H5: High | I5: Fiqh ruling; Safety or abuse; External resource or teacher; Tone and pastoral wording | J5: Scholar; Mentor | K5: not tracked | L5: 3 | M5: new-muslim-academy — New Muslim Academy (New Muslim Academy) whyislam — WhyIslam (Islamic Circle of North America) new-muslim-guide — New Muslim Guide (New Muslim Guide) | X5: https://www.revertguide.com/en/roadmap/day-0-1#overview-heading | Y5: day-0-1 | Z5: locales/en/stages.json › [id=day-0-1].dontWorry | AA5: stage:day-0-1
A6: R0005 | B6: Roadmap stage | C6: Faith and a fresh start | D6: Focus now | E6: • Hold on to what the Shahada means to you. • Make Ghusl when you have time to do it calmly. • Pick one person or one masjid you can contact. | F6: • শাহাদা আপনার কাছে কী, তা আঁকড়ে ধরুন। • শান্তভাবে করার মতো সময় পেলে গোসল করুন। • যোগাযোগ করা যায় এমন একজন মানুষ বা একটি মসজিদ বেছে নিন। | G6: Translated | H6: High | I6: Fiqh ruling; Safety or abuse; External resource or teacher; Tone and pastoral wording | J6: Scholar; Mentor | K6: not tracked | L6: 3 | M6: new-muslim-academy — New Muslim Academy (New Muslim Academy) whyislam — WhyIslam (Islamic Circle of North America) new-muslim-guide — New Muslim Guide (New Muslim Guide) | X6: https://www.revertguide.com/en/roadmap/day-0-1#stage-guidance-heading | Y6: day-0-1 | Z6: locales/en/stages.json › [id=day-0-1].focusNow | AA6: stage:day-0-1
A7: R0006 | B7: Roadmap stage | C7: Faith and a fresh start | D7: Can wait | E7: • Detailed rulings and the arguments around them. • Changing your name, your wardrobe, or your whole routine at once. • Explaining Islam to everyone you know. | F7: • বিস্তারিত বিধান আর সেগুলো ঘিরে তর্ক। • একসাথে নাম, পোশাক বা পুরো রুটিন বদলানো। • পরিচিত সবাইকে ইসলাম বোঝানো। | G7: Translated | H7: High | I7: Fiqh ruling; Safety or abuse; External resource or teacher; Tone and pastoral wording | J7: Scholar; Mentor | K7: not tracked | L7: 3 | M7: new-muslim-academy — New Muslim Academy (New Muslim Academy) whyislam — WhyIslam (Islamic Circle of North America) new-muslim-guide — New Muslim Guide (New Muslim Guide) | X7: https://www.revertguide.com/en/roadmap/day-0-1#stage-guidance-heading | Y7: day-0-1 | Z7: locales/en/stages.json › [id=day-0-1].canWait | AA7: stage:day-0-1
A8: R0007 | B8: Roadmap stage | C8: Faith and a fresh start | D8: Ask for help if | E8: • You do not feel safe telling your family. • You are not sure how to do Ghusl. • You need a witness, a certificate, or a way into a local community. | F8: • পরিবারকে জানানো নিরাপদ মনে না হয়। • কীভাবে গোসল করবেন নিশ্চিত না হন। • সাক্ষী, সনদ বা স্থানীয় কমিউনিটিতে ঢোকার পথ দরকার হয়। | G8: Translated | H8: High | I8: Fiqh ruling; Safety or abuse; External resource or teacher; Tone and pastoral wording | J8: Scholar; Mentor | K8: not tracked | L8: 3 | M8: new-muslim-academy — New Muslim Academy (New Muslim Academy) whyislam — WhyIslam (Islamic Circle of North America) new-muslim-guide — New Muslim Guide (New Muslim Guide) | X8: https://www.revertguide.com/en/roadmap/day-0-1#stage-guidance-heading | Y8: day-0-1 | Z8: locales/en/stages.json › [id=day-0-1].askHelpIf | AA8: stage:day-0-1
A9: R0008 | B9: Roadmap stage | C9: Faith and a fresh start | D9: Learning path: main resource | E9: Welcome to Islam: A Step-by-Step Guide for New Muslims A 32-page guide by Mustafa Umar, a scholar and imam, written for your first month. You can read the whole thing free on his website. Link: https://mustafaumar.com/downloads/welcome-to-islam/ | F9: Welcome to Islam: A Step-by-Step Guide for New Muslims (নতুন মুসলিমদের জন্য ধাপে ধাপে গাইড) আলেম ও ইমাম মুস্তাফা উমরের লেখা 32 পৃষ্ঠার একটি গাইড, আপনার প্রথম মাসের জন্য। তার ওয়েবসাইটে পুরোটা বিনামূল্যে পড়া যায়। | G9: Translated | H9: High | I9: Fiqh ruling; Safety or abuse; External resource or teacher; Tone and pastoral wording | J9: Scholar; Mentor | K9: not tracked | L9: 3 | M9: new-muslim-academy — New Muslim Academy (New Muslim Academy) whyislam — WhyIslam (Islamic Circle of North America) new-muslim-guide — New Muslim Guide (New Muslim Guide) | X9: https://www.revertguide.com/en/roadmap/day-0-1#learning-path-heading | Y9: day-0-1 | Z9: locales/en/stages.json › [id=day-0-1].learningPath.main | AA9: stage:day-0-1
A10: R0009 | B10: Roadmap stage | C10: Faith and a fresh start | D10: Learning path: optional resource | E10: Your first 24 hours If you would rather read something shorter, this step covers what matters today and what can wait. | F10: আপনার প্রথম 24 ঘণ্টা আরও ছোট কিছু পড়তে চাইলে এই ধাপে আছে আজ কী জরুরি আর কী অপেক্ষা করতে পারে। | G10: Translated | H10: High | I10: Fiqh ruling; Safety or abuse; External resource or teacher; Tone and pastoral wording | J10: Scholar; Mentor | K10: not tracked | L10: 3 | M10: new-muslim-academy — New Muslim Academy (New Muslim Academy) whyislam — WhyIslam (Islamic Circle of North America) new-muslim-guide — New Muslim Guide (New Muslim Guide) | X10: https://www.revertguide.com/en/roadmap/day-0-1#learning-path-heading | Y10: day-0-1 | Z10: locales/en/stages.json › [id=day-0-1].learningPath.optional | AA10: stage:day-0-1
A11: R0010 | B11: Roadmap stage | C11: Faith and a fresh start | D11: Learning path: guardrails | E11: • No course, no app and no Arabic study is needed today. • Rest is part of this stage. You do not have to learn everything this week. | F11: • আজ কোনো কোর্স, অ্যাপ বা আরবি পড়াশোনার দরকার নেই। • বিশ্রাম এই পর্যায়েরই অংশ। এই সপ্তাহে সব শিখতে হবে না। | G11: Translated | H11: High | I11: Fiqh ruling; Safety or abuse; External resource or teacher; Tone and pastoral wording | J11: Scholar; Mentor | K11: not tracked | L11: 3 | M11: new-muslim-academy — New Muslim Academy (New Muslim Academy) whyislam — WhyIslam (Islamic Circle of North America) new-muslim-guide — New Muslim Guide (New Muslim Guide) | X11: https://www.revertguide.com/en/roadmap/day-0-1#learning-path-heading | Y11: day-0-1 | Z11: locales/en/stages.json › [id=day-0-1].learningPath.guardrails | AA11: stage:day-0-1
A12: R0011 | B12: Roadmap stage | C12: Faith and a fresh start | D12: Good next questions | E12: • What do I do first? → /topics/new-muslim-basics • How do I talk to family? → /topics/family-and-identity | F12: • প্রথমে কী করব? → /topics/new-muslim-basics • পরিবারের সাথে কীভাবে কথা বলব? → /topics/family-and-identity | G12: Translated | H12: High | I12: Fiqh ruling; Safety or abuse; External resource or teacher; Tone and pastoral wording | J12: Scholar; Mentor | K12: not tracked | L12: 3 | M12: new-muslim-academy — New Muslim Academy (New Muslim Academy) whyislam — WhyIslam (Islamic Circle of North America) new-muslim-guide — New Muslim Guide (New Muslim Guide) | X12: https://www.revertguide.com/en/roadmap/day-0-1#good-questions-heading | Y12: day-0-1 | Z12: locales/en/stages.json › [id=day-0-1].goodNextQuestions | AA12: stage:day-0-1
A13: R0012 | B13: Roadmap stage | C13: Getting the basics in place | D13: Title, subtitle and description | E13: Getting the basics in place Week 1 Duration: About 1 week This week is for gentle practice. You learn the shape of prayer, visit or at least phone a masjid, and start using short remembrance. None of it has to be done perfectly. | F13: মূল বিষয়গুলো জায়গামতো বসানো সপ্তাহ 1 Duration: প্রায় 1 সপ্তাহ এই সপ্তাহ নরম অনুশীলনের। আপনি নামাজের গঠন শিখবেন, একটি মসজিদে যাবেন বা অন্তত ফোন করবেন, আর ছোট ছোট জিকির শুরু করবেন। কোনোটিই নিখুঁত হতে হবে না। | G13: Translated | H13: Medium | I13: External resource or teacher; Tone and pastoral wording | J13: Scholar; Mentor | K13: not tracked | L13: 3 | M13: new-muslim-guide — New Muslim Guide (New Muslim Guide) seekersguidance — SeekersGuidance (SeekersGuidance) whyislam — WhyIslam (Islamic Circle of North America) | N13: • Says missing prayers while still learning is normal, and optional practices can wait until the required ones feel steady. • Recommends Quran.com's free 'Seven Days, Seven Verses' Al-Fatihah plan, readable without an account. • Recommends the New Muslim Academy prayer course and says it needs an account and the site uses analytics and an advertising pixel; confirm still true. | X13: https://www.revertguide.com/en/roadmap/week-1 | Y13: week-1 | Z13: locales/en/stages.json › [id=week-1].title/subtitle/description | AA13: stage:week-1
A14: R0013 | B14: Roadmap stage | C14: Getting the basics in place | D14: Main goal | E14: Start praying in a way you can actually keep up, and make one first contact with other Muslims. | F14: এমনভাবে নামাজ শুরু করা যা সত্যিই ধরে রাখতে পারবেন, আর অন্য মুসলিমদের সাথে প্রথম যোগাযোগ করা। | G14: Translated | H14: Medium | I14: External resource or teacher; Tone and pastoral wording | J14: Scholar; Mentor | K14: not tracked | L14: 3 | M14: new-muslim-guide — New Muslim Guide (New Muslim Guide) seekersguidance — SeekersGuidance (SeekersGuidance) whyislam — WhyIslam (Islamic Circle of North America) | X14: https://www.revertguide.com/en/roadmap/week-1#overview-heading | Y14: week-1 | Z14: locales/en/stages.json › [id=week-1].mainGoal | AA14: stage:week-1
A15: R0014 | B15: Roadmap stage | C15: Getting the basics in place | D15: Success looks like | E15: You are praying in some form and you know where to go locally when you need help. | F15: আপনি কোনো না কোনো রূপে নামাজ পড়ছেন, আর সাহায্য দরকার হলে স্থানীয়ভাবে কোথায় যাবেন তা জানেন। | G15: Translated | H15: Medium | I15: External resource or teacher; Tone and pastoral wording | J15: Scholar; Mentor | K15: not tracked | L15: 3 | M15: new-muslim-guide — New Muslim Guide (New Muslim Guide) seekersguidance — SeekersGuidance (SeekersGuidance) whyislam — WhyIslam (Islamic Circle of North America) | X15: https://www.revertguide.com/en/roadmap/week-1#overview-heading | Y15: week-1 | Z15: locales/en/stages.json › [id=week-1].success | AA15: stage:week-1
A16: R0015 | B16: Roadmap stage | C16: Getting the basics in place | D16: Don't worry about | E16: • Your Arabic pronunciation does not have to be right yet. • Missing prayers while you are still learning is normal. • Feeling out of place at the masjid the first few times is normal too. • Optional practices can wait until the required ones feel steady. | F16: • আপনার আরবি উচ্চারণ এখনো ঠিক হতে হবে না। • শেখা চলাকালীন নামাজ ছুটে যাওয়া স্বাভাবিক। • প্রথম কয়েকবার মসজিদে বেমানান লাগাও স্বাভাবিক। • ফরজগুলো স্থির না হওয়া পর্যন্ত নফল আমল অপেক্ষা করতে পারে। | G16: Translated | H16: Medium | I16: External resource or teacher; Tone and pastoral wording | J16: Scholar; Mentor | K16: not tracked | L16: 3 | M16: new-muslim-guide — New Muslim Guide (New Muslim Guide) seekersguidance — SeekersGuidance (SeekersGuidance) whyislam — WhyIslam (Islamic Circle of North America) | X16: https://www.revertguide.com/en/roadmap/week-1#overview-heading | Y16: week-1 | Z16: locales/en/stages.json › [id=week-1].dontWorry | AA16: stage:week-1
A17: R0016 | B17: Roadmap stage | C17: Getting the basics in place | D17: Focus now | E17: • Learn the prayer times and the basic movements. • Find one masjid or one mentor you can ask questions. • Use short dua and dhikr to keep your heart in it. | F17: • নামাজের সময় আর মূল নড়াচড়াগুলো শিখুন। • প্রশ্ন করা যায় এমন একটি মসজিদ বা একজন মেন্টর খুঁজুন। • মন ধরে রাখতে ছোট দোয়া আর জিকির ব্যবহার করুন। | G17: Translated | H17: Medium | I17: External resource or teacher; Tone and pastoral wording | J17: Scholar; Mentor | K17: not tracked | L17: 3 | M17: new-muslim-guide — New Muslim Guide (New Muslim Guide) seekersguidance — SeekersGuidance (SeekersGuidance) whyislam — WhyIslam (Islamic Circle of North America) | X17: https://www.revertguide.com/en/roadmap/week-1#stage-guidance-heading | Y17: week-1 | Z17: locales/en/stages.json › [id=week-1].focusNow | AA17: stage:week-1
A18: R0017 | B18: Roadmap stage | C18: Getting the basics in place | D18: Can wait | E18: • Optional prayers and the finer differences of opinion. • Learning every custom at every masjid. • Big Arabic memorization goals. | F18: • নফল নামাজ আর মতভেদের সূক্ষ্ম খুঁটিনাটি। • প্রতিটি মসজিদের প্রতিটি প্রথা শেখা। • বড় বড় আরবি মুখস্থের লক্ষ্য। | G18: Translated | H18: Medium | I18: External resource or teacher; Tone and pastoral wording | J18: Scholar; Mentor | K18: not tracked | L18: 3 | M18: new-muslim-guide — New Muslim Guide (New Muslim Guide) seekersguidance — SeekersGuidance (SeekersGuidance) whyislam — WhyIslam (Islamic Circle of North America) | X18: https://www.revertguide.com/en/roadmap/week-1#stage-guidance-heading | Y18: week-1 | Z18: locales/en/stages.json › [id=week-1].canWait | AA18: stage:week-1
A19: R0018 | B19: Roadmap stage | C19: Getting the basics in place | D19: Ask for help if | E19: • The basics of prayer still confuse you. • Walking into a masjid makes you nervous. • Work or school makes prayer times hard to hit. | F19: • নামাজের মূল বিষয়গুলো এখনো বিভ্রান্ত করে। • মসজিদে ঢুকতে ভয় ভয় লাগে। • কাজ বা স্কুলের কারণে নামাজের সময় ধরা কঠিন হয়। | G19: Translated | H19: Medium | I19: External resource or teacher; Tone and pastoral wording | J19: Scholar; Mentor | K19: not tracked | L19: 3 | M19: new-muslim-guide — New Muslim Guide (New Muslim Guide) seekersguidance — SeekersGuidance (SeekersGuidance) whyislam — WhyIslam (Islamic Circle of North America) | X19: https://www.revertguide.com/en/roadmap/week-1#stage-guidance-heading | Y19: week-1 | Z19: locales/en/stages.json › [id=week-1].askHelpIf | AA19: stage:week-1
A20: R0019 | B20: Roadmap stage | C20: Getting the basics in place | D20: Learning path: main resource | E20: Seven Days, Seven Verses (Al-Fatihah) A free Quran.com plan that takes one verse of Al-Fatihah a day, word by word with its meaning, in under ten minutes. You can read it without an account. Listen to a clear reciter and repeat after them. Link: https://quran.com/learning-plans/seven-days-seven-verses-living-the-message-of-al-fatihah | F20: Seven Days, Seven Verses (সাত দিনে সূরা আল-ফাতিহার সাত আয়াত) Quran.com-এর একটি বিনামূল্যের পরিকল্পনা, যাতে দিনে সূরা আল-ফাতিহার একটি আয়াত, শব্দে শব্দে অর্থসহ, দশ মিনিটেরও কম সময়ে পড়া হয়। অ্যাকাউন্ট ছাড়াই পড়া যায়। স্পষ্ট তিলাওয়াতকারী কারও পড়া শুনুন আর তার পরে পরে বলুন। | G20: Translated | H20: Medium | I20: External resource or teacher; Tone and pastoral wording | J20: Scholar; Mentor | K20: not tracked | L20: 3 | M20: new-muslim-guide — New Muslim Guide (New Muslim Guide) seekersguidance — SeekersGuidance (SeekersGuidance) whyislam — WhyIslam (Islamic Circle of North America) | X20: https://www.revertguide.com/en/roadmap/week-1#learning-path-heading | Y20: week-1 | Z20: locales/en/stages.json › [id=week-1].learningPath.main | AA20: stage:week-1
A21: R0020 | B21: Roadmap stage | C21: Getting the basics in place | D21: Learning path: optional resource | E21: New Muslim Academy prayer course A free course that starts with wudu and prayer videos and short quizzes. You need an account, and the site uses analytics and an advertising pixel. Link: https://www.newmuslimacademy.org/ | F21: New Muslim Academy-র নামাজ কোর্স একটি বিনামূল্যের কোর্স, যা ওযু আর নামাজের ভিডিও আর ছোট কুইজ দিয়ে শুরু হয়। একটি অ্যাকাউন্ট লাগে, আর সাইটটি অ্যানালিটিক্স আর একটি বিজ্ঞাপনী পিক্সেল ব্যবহার করে। | G21: Translated | H21: Medium | I21: External resource or teacher; Tone and pastoral wording | J21: Scholar; Mentor | K21: not tracked | L21: 3 | M21: new-muslim-guide — New Muslim Guide (New Muslim Guide) seekersguidance — SeekersGuidance (SeekersGuidance) whyislam — WhyIslam (Islamic Circle of North America) | X21: https://www.revertguide.com/en/roadmap/week-1#learning-path-heading | Y21: week-1 | Z21: locales/en/stages.json › [id=week-1].learningPath.optional | AA21: stage:week-1
A22: R0021 | B22: Roadmap stage | C22: Getting the basics in place | D22: Learning path: guardrails | E22: • Learn the shape of the prayer first. Memorising takes weeks, and that is normal. • One course at a time is plenty. | F22: • আগে নামাজের গঠন শিখুন। মুখস্থ করতে কয়েক সপ্তাহ লাগে, আর তা স্বাভাবিক। • এক সময়ে একটি কোর্সই যথেষ্ট। | G22: Translated | H22: Medium | I22: External resource or teacher; Tone and pastoral wording | J22: Scholar; Mentor | K22: not tracked | L22: 3 | M22: new-muslim-guide — New Muslim Guide (New Muslim Guide) seekersguidance — SeekersGuidance (SeekersGuidance) whyislam — WhyIslam (Islamic Circle of North America) | X22: https://www.revertguide.com/en/roadmap/week-1#learning-path-heading | Y22: week-1 | Z22: locales/en/stages.json › [id=week-1].learningPath.guardrails | AA22: stage:week-1
A23: R0022 | B23: Roadmap stage | C23: Getting the basics in place | D23: Good next questions | E23: • How do I visit a masjid? → /topics/masjid-and-community • How do I build prayer slowly? → /topics/prayer | F23: • কীভাবে মসজিদে যাব? → /topics/masjid-and-community • কীভাবে ধীরে ধীরে নামাজ গড়ে তুলব? → /topics/prayer | G23: Translated | H23: Medium | I23: External resource or teacher; Tone and pastoral wording | J23: Scholar; Mentor | K23: not tracked | L23: 3 | M23: new-muslim-guide — New Muslim Guide (New Muslim Guide) seekersguidance — SeekersGuidance (SeekersGuidance) whyislam — WhyIslam (Islamic Circle of North America) | X23: https://www.revertguide.com/en/roadmap/week-1#good-questions-heading | Y23: week-1 | Z23: locales/en/stages.json › [id=week-1].goodNextQuestions | AA23: stage:week-1
A24: R0023 | B24: Roadmap stage | C24: Settling into practice | D24: Title, subtitle and description | E24: Settling into practice Weeks 2-4 Duration: 2-3 weeks Things are starting to settle. Now you add the Quran, work out what to say to family, and find a healthier way to handle the questions that come up without drowning in them. | F24: আমলে থিতু হওয়া সপ্তাহ 2-4 Duration: 2-3 সপ্তাহ সবকিছু থিতু হতে শুরু করেছে। এখন কুরআন যোগ করবেন, পরিবারকে কী বলবেন ঠিক করবেন, আর যে প্রশ্নগুলো আসে সেগুলোয় ডুবে না গিয়ে সামলানোর একটি সুস্থ উপায় খুঁজবেন। | G24: Translated | H24: Medium | I24: External resource or teacher; Tone and pastoral wording | J24: Scholar; Mentor | K24: not tracked | L24: 3 | M24: quran-com — Quran.com (Quran Foundation) yaqeen-institute — Yaqeen Institute (Yaqeen Institute for Islamic Research) seekersguidance — SeekersGuidance (SeekersGuidance) | N24: • Recommends a masjid Arabic-reading class (letters, vowels, joining, short surahs) with The Clear Quran or Abdel Haleem's translation. • Recommends New Muslim Academy live Quran classes: free, evenings Eastern time, brothers and sisters taught separately, sign-up form first. • Ask-for-help triggers include family pressure turning unsafe or controlling and doubts that stop you functioning; no contacts are named. • Guardrails: free before paid, and be careful with one-to-one tutoring from academies you cannot check. | X24: https://www.revertguide.com/en/roadmap/week-2-3 | Y24: week-2-3 | Z24: locales/en/stages.json › [id=week-2-3].title/subtitle/description | AA24: stage:week-2-3
A25: R0024 | B25: Roadmap stage | C25: Settling into practice | D25: Main goal | E25: Start a small Quran habit, get ready for the conversations with family and friends, and learn how to ask a question well. | F25: কুরআনের একটি ছোট অভ্যাস শুরু করা, পরিবার ও বন্ধুদের সাথে আলাপের জন্য তৈরি হওয়া, আর ভালোভাবে প্রশ্ন করা শেখা। | G25: Translated | H25: Medium | I25: External resource or teacher; Tone and pastoral wording | J25: Scholar; Mentor | K25: not tracked | L25: 3 | M25: quran-com — Quran.com (Quran Foundation) yaqeen-institute — Yaqeen Institute (Yaqeen Institute for Islamic Research) seekersguidance — SeekersGuidance (SeekersGuidance) | X25: https://www.revertguide.com/en/roadmap/week-2-3#overview-heading | Y25: week-2-3 | Z25: locales/en/stages.json › [id=week-2-3].mainGoal | AA25: stage:week-2-3
A26: R0025 | B26: Roadmap stage | C26: Settling into practice | D26: Success looks like | E26: You read or listen to some Quran regularly, you have a line or two ready for the people closest to you, and doubts do not knock you over the way they did. | F26: আপনি নিয়মিত কিছু কুরআন পড়েন বা শোনেন, সবচেয়ে কাছের মানুষদের জন্য এক-দুই লাইন তৈরি আছে, আর সংশয় আগের মতো আপনাকে ধরাশায়ী করে না। | G26: Translated | H26: Medium | I26: External resource or teacher; Tone and pastoral wording | J26: Scholar; Mentor | K26: not tracked | L26: 3 | M26: quran-com — Quran.com (Quran Foundation) yaqeen-institute — Yaqeen Institute (Yaqeen Institute for Islamic Research) seekersguidance — SeekersGuidance (SeekersGuidance) | X26: https://www.revertguide.com/en/roadmap/week-2-3#overview-heading | Y26: week-2-3 | Z26: locales/en/stages.json › [id=week-2-3].success | AA26: stage:week-2-3
A27: R0026 | B27: Roadmap stage | C27: Settling into practice | D27: Don't worry about | E27: • Reading Arabic fluently is a long way off for almost everyone. • You will not understand every verse. Neither does anyone else on a first read. • Faith going up and down does not mean it is failing. • You do not have to win any arguments. | F27: • সাবলীলভাবে আরবি পড়া প্রায় সবার জন্যই অনেক দূরের ব্যাপার। • আপনি প্রতিটি আয়াত বুঝবেন না। প্রথমবার পড়ে অন্য কেউও বোঝেন না। • ঈমান ওঠানামা করা মানে তা ব্যর্থ হচ্ছে না। • কোনো তর্কে জিততে হবে না। | G27: Translated | H27: Medium | I27: External resource or teacher; Tone and pastoral wording | J27: Scholar; Mentor | K27: not tracked | L27: 3 | M27: quran-com — Quran.com (Quran Foundation) yaqeen-institute — Yaqeen Institute (Yaqeen Institute for Islamic Research) seekersguidance — SeekersGuidance (SeekersGuidance) | X27: https://www.revertguide.com/en/roadmap/week-2-3#overview-heading | Y27: week-2-3 | Z27: locales/en/stages.json › [id=week-2-3].dontWorry | AA27: stage:week-2-3
A28: R0027 | B28: Roadmap stage | C28: Settling into practice | D28: Focus now | E28: • Read or listen to a little Quran on a regular basis. • Decide who needs to know about your Islam, and when. • Take the hard questions to people who actually know. | F28: • নিয়মিত একটু একটু কুরআন পড়ুন বা শুনুন। • আপনার ইসলাম সম্পর্কে কার জানা দরকার, আর কখন, তা ঠিক করুন। • কঠিন প্রশ্নগুলো তাদের কাছে নিয়ে যান যারা সত্যিই জানেন। | G28: Translated | H28: Medium | I28: External resource or teacher; Tone and pastoral wording | J28: Scholar; Mentor | K28: not tracked | L28: 3 | M28: quran-com — Quran.com (Quran Foundation) yaqeen-institute — Yaqeen Institute (Yaqeen Institute for Islamic Research) seekersguidance — SeekersGuidance (SeekersGuidance) | X28: https://www.revertguide.com/en/roadmap/week-2-3#stage-guidance-heading | Y28: week-2-3 | Z28: locales/en/stages.json › [id=week-2-3].focusNow | AA28: stage:week-2-3
A29: R0028 | B29: Roadmap stage | C29: Settling into practice | D29: Can wait | E29: • Public debates and internet arguments. • Tafsir study and Arabic grammar. • Answering every family objection on the spot. | F29: • প্রকাশ্য বিতর্ক আর ইন্টারনেটের তর্ক। • তাফসির পড়া আর আরবি ব্যাকরণ। • পরিবারের প্রতিটি আপত্তির সঙ্গে সঙ্গে জবাব দেওয়া। | G29: Translated | H29: Medium | I29: External resource or teacher; Tone and pastoral wording | J29: Scholar; Mentor | K29: not tracked | L29: 3 | M29: quran-com — Quran.com (Quran Foundation) yaqeen-institute — Yaqeen Institute (Yaqeen Institute for Islamic Research) seekersguidance — SeekersGuidance (SeekersGuidance) | X29: https://www.revertguide.com/en/roadmap/week-2-3#stage-guidance-heading | Y29: week-2-3 | Z29: locales/en/stages.json › [id=week-2-3].canWait | AA29: stage:week-2-3
A30: R0029 | B30: Roadmap stage | C30: Settling into practice | D30: Ask for help if | E30: • Family pressure turns unsafe or controlling. • Doubts are stopping you from functioning. • You cannot tell which sources are reliable. | F30: • পরিবারের চাপ অনিরাপদ বা নিয়ন্ত্রণমূলক হয়ে ওঠে। • সংশয় আপনাকে দৈনন্দিন কাজ করতে দিচ্ছে না। • কোন সূত্রগুলো নির্ভরযোগ্য বুঝতে পারছেন না। | G30: Translated | H30: High | I30: Safety or abuse; External resource or teacher; Tone and pastoral wording | J30: Scholar; Mentor | K30: not tracked | L30: 3 | M30: quran-com — Quran.com (Quran Foundation) yaqeen-institute — Yaqeen Institute (Yaqeen Institute for Islamic Research) seekersguidance — SeekersGuidance (SeekersGuidance) | X30: https://www.revertguide.com/en/roadmap/week-2-3#stage-guidance-heading | Y30: week-2-3 | Z30: locales/en/stages.json › [id=week-2-3].askHelpIf | AA30: stage:week-2-3
A31: R0030 | B31: Roadmap stage | C31: Settling into practice | D31: Learning path: main resource | E31: A beginners' Quran reading class at a masjid Ask your local masjid whether it runs a class for learning to read Arabic. Most start with the letters, then the vowel marks, then joining letters, then short surahs. Alongside it, pick one translation, such as The Clear Quran or Abdel Haleem's, and read a little each day. | F31: মসজিদে নতুনদের কুরআন পড়ার ক্লাস আপনার এলাকার মসজিদে জিজ্ঞেস করুন আরবি পড়া শেখার কোনো ক্লাস চালায় কি না। বেশিরভাগ ক্লাস অক্ষর দিয়ে শুরু হয়, তারপর স্বরচিহ্ন, তারপর অক্ষর জোড়া, তারপর ছোট সূরা। এর পাশাপাশি একটি অনুবাদ বেছে নিন, যেমন The Clear Quran বা আবদেল হালিমের অনুবাদ, আর প্রতিদিন একটু পড়ুন। | G31: Translated | H31: Medium | I31: Quran or hadith citation; External resource or teacher; Tone and pastoral wording | J31: Scholar; Mentor | K31: not tracked | L31: 3 | M31: quran-com — Quran.com (Quran Foundation) yaqeen-institute — Yaqeen Institute (Yaqeen Institute for Islamic Research) seekersguidance — SeekersGuidance (SeekersGuidance) | X31: https://www.revertguide.com/en/roadmap/week-2-3#learning-path-heading | Y31: week-2-3 | Z31: locales/en/stages.json › [id=week-2-3].learningPath.main | AA31: stage:week-2-3
A32: R0031 | B32: Roadmap stage | C32: Settling into practice | D32: Learning path: optional resource | E32: New Muslim Academy live Quran classes Free small-group classes online in the evening, Eastern time, with brothers and sisters taught separately. They cover Al-Fatihah and short surahs. You fill in a sign-up form first. Link: https://www.newmuslimacademy.org/sisters-quran-classes/ | F32: New Muslim Academy-র লাইভ কুরআন ক্লাস সন্ধ্যায়, পূর্বাঞ্চলীয় সময়ে, অনলাইনে ছোট দলের বিনামূল্যের ক্লাস, ভাই আর বোনদের আলাদাভাবে পড়ানো হয়। সূরা আল-ফাতিহা আর ছোট সূরাগুলো শেখানো হয়। আগে একটি নিবন্ধন ফর্ম পূরণ করতে হয়। | G32: Translated | H32: Medium | I32: Quran or hadith citation; External resource or teacher; Tone and pastoral wording | J32: Scholar; Mentor | K32: not tracked | L32: 3 | M32: quran-com — Quran.com (Quran Foundation) yaqeen-institute — Yaqeen Institute (Yaqeen Institute for Islamic Research) seekersguidance — SeekersGuidance (SeekersGuidance) | X32: https://www.revertguide.com/en/roadmap/week-2-3#learning-path-heading | Y32: week-2-3 | Z32: locales/en/stages.json › [id=week-2-3].learningPath.optional | AA32: stage:week-2-3
A33: R0032 | B33: Roadmap stage | C33: Settling into practice | D33: Learning path: guardrails | E33: • Free before paid. You do not need a paid online tutor to start. • Be careful with one-to-one tutoring from academies you cannot check. | F33: • টাকার আগে বিনামূল্যেরটা। শুরু করতে টাকা দিয়ে অনলাইন শিক্ষক লাগবে না। • যাচাই করতে পারেন না এমন একাডেমির একান্ত টিউশনের ব্যাপারে সাবধান থাকুন। | G33: Translated | H33: Medium | I33: External resource or teacher; Tone and pastoral wording | J33: Scholar; Mentor | K33: not tracked | L33: 3 | M33: quran-com — Quran.com (Quran Foundation) yaqeen-institute — Yaqeen Institute (Yaqeen Institute for Islamic Research) seekersguidance — SeekersGuidance (SeekersGuidance) | X33: https://www.revertguide.com/en/roadmap/week-2-3#learning-path-heading | Y33: week-2-3 | Z33: locales/en/stages.json › [id=week-2-3].learningPath.guardrails | AA33: stage:week-2-3
A34: R0033 | B34: Roadmap stage | C34: Settling into practice | D34: Good next questions | E34: • What if I have doubts? → /topics/questions-and-doubts • How do I protect family ties? → /topics/family-and-identity | F34: • সংশয় এলে কী করব? → /topics/questions-and-doubts • কীভাবে আত্মীয়তার সম্পর্ক রক্ষা করব? → /topics/family-and-identity | G34: Translated | H34: Medium | I34: External resource or teacher; Tone and pastoral wording | J34: Scholar; Mentor | K34: not tracked | L34: 3 | M34: quran-com — Quran.com (Quran Foundation) yaqeen-institute — Yaqeen Institute (Yaqeen Institute for Islamic Research) seekersguidance — SeekersGuidance (SeekersGuidance) | X34: https://www.revertguide.com/en/roadmap/week-2-3#good-questions-heading | Y34: week-2-3 | Z34: locales/en/stages.json › [id=week-2-3].goodNextQuestions | AA34: stage:week-2-3
A35: R0034 | B35: Roadmap stage | C35: Islam in daily life | D35: Title, subtitle and description | E35: Islam in daily life Months 2-3 Duration: 1-2 months Here Islam works its way into ordinary days: what you eat, how you get ready for fasting, how you dress, and where you draw practical lines. Set the pace so you can keep it up. | F35: দৈনন্দিন জীবনে ইসলাম মাস 2-3 Duration: 1-2 মাস এখানে ইসলাম সাধারণ দিনগুলোর ভেতরে ঢুকে পড়ে: কী খান, রোজার জন্য কীভাবে তৈরি হন, কী পরেন, আর কোথায় ব্যবহারিক সীমা টানেন। এমন গতি ঠিক করুন যা ধরে রাখতে পারবেন। | G35: Translated | H35: Medium | I35: External resource or teacher; Tone and pastoral wording | J35: Scholar; Mentor | K35: not tracked | L35: 2 | M35: new-muslim-guide — New Muslim Guide (New Muslim Guide) seekersguidance — SeekersGuidance (SeekersGuidance) | N35: • Recommends New Muslim Academy core courses or SeekersGuidance's free live 'Essentials of Faith, Worship, and Spirituality', Saturdays 10:00 Eastern; confirm the schedule. • Recommends Quran.com learning plans for short surahs such as Al-Ikhlas, Al-Falaq and An-Nas. • Ask-for-help triggers: food or clothing pressure risking safety at home, a medical condition affecting fasting, a ruling on work, school or money. • Guardrail: choose a prayer times app that keeps your location on your phone and has no ads. | X35: https://www.revertguide.com/en/roadmap/month-1-2 | Y35: month-1-2 | Z35: locales/en/stages.json › [id=month-1-2].title/subtitle/description | AA35: stage:month-1-2
A36: R0035 | B36: Roadmap stage | C36: Islam in daily life | D36: Main goal | E36: Learn the halal basics, get ready for fasting, and treat modesty as something you grow into rather than something to panic about. | F36: হালালের মূল বিষয় শেখা, রোজার জন্য তৈরি হওয়া, আর শালীনতাকে আতঙ্কের বিষয় না ভেবে ধীরে ধীরে অভ্যস্ত হওয়ার বিষয় হিসেবে দেখা। | G36: Translated | H36: Medium | I36: Mental health; External resource or teacher; Tone and pastoral wording | J36: Scholar; Mentor; Mental health professional | K36: not tracked | L36: 2 | M36: new-muslim-guide — New Muslim Guide (New Muslim Guide) seekersguidance — SeekersGuidance (SeekersGuidance) | X36: https://www.revertguide.com/en/roadmap/month-1-2#overview-heading | Y36: month-1-2 | Z36: locales/en/stages.json › [id=month-1-2].mainGoal | AA36: stage:month-1-2
A37: R0036 | B37: Roadmap stage | C37: Islam in daily life | D37: Success looks like | E37: You can shop and order food without stress, you know how fasting works at a beginner level, and you can tell which lifestyle questions need a local answer. | F37: চাপ ছাড়াই বাজার করতে আর খাবার অর্ডার দিতে পারেন, নতুনদের স্তরে রোজা কীভাবে কাজ করে জানেন, আর বুঝতে পারেন জীবনযাপনের কোন প্রশ্নের স্থানীয় উত্তর দরকার। | G37: Translated | H37: Medium | I37: External resource or teacher; Tone and pastoral wording | J37: Scholar; Mentor | K37: not tracked | L37: 2 | M37: new-muslim-guide — New Muslim Guide (New Muslim Guide) seekersguidance — SeekersGuidance (SeekersGuidance) | X37: https://www.revertguide.com/en/roadmap/month-1-2#overview-heading | Y37: month-1-2 | Z37: locales/en/stages.json › [id=month-1-2].success | AA37: stage:month-1-2
A38: R0037 | B38: Roadmap stage | C38: Islam in daily life | D38: Don't worry about | E38: • Your whole pantry does not have to change overnight. • One unclear ingredient is not an emergency. • How fast someone else changed their clothing has nothing to do with you. • Random online comments are not the place to sort out questions about fasting and hardship. | F38: • রাতারাতি পুরো রান্নাঘরের মজুত বদলাতে হবে না। • একটি অস্পষ্ট উপাদান জরুরি অবস্থা নয়। • অন্য কেউ কত দ্রুত পোশাক বদলেছেন, তার সাথে আপনার কোনো সম্পর্ক নেই। • রোজা আর কষ্টকর অবস্থা নিয়ে প্রশ্নের মীমাংসার জায়গা অনলাইনের এলোমেলো মন্তব্য নয়। | G38: Translated | H38: High | I38: Safety or abuse; External resource or teacher; Tone and pastoral wording | J38: Scholar; Mentor | K38: not tracked | L38: 2 | M38: new-muslim-guide — New Muslim Guide (New Muslim Guide) seekersguidance — SeekersGuidance (SeekersGuidance) | X38: https://www.revertguide.com/en/roadmap/month-1-2#overview-heading | Y38: month-1-2 | Z38: locales/en/stages.json › [id=month-1-2].dontWorry | AA38: stage:month-1-2
A39: R0038 | B39: Roadmap stage | C39: Islam in daily life | D39: Focus now | E39: • Steer clear of the clearly haram foods and get comfortable with simple halal choices. • Learn how fasting works before Ramadan or your first voluntary fast. • Change one thing at a time with clothing, and keep it sustainable. | F39: • স্পষ্টভাবে হারাম খাবার থেকে দূরে থাকুন, আর সহজ হালাল বিকল্পে স্বচ্ছন্দ হোন। • রমজান বা প্রথম নফল রোজার আগে রোজা কীভাবে কাজ করে শিখুন। • পোশাকে এক সময়ে একটি জিনিস বদলান, আর তা টেকসই রাখুন। | G39: Translated | H39: Medium | I39: External resource or teacher; Tone and pastoral wording | J39: Scholar; Mentor | K39: not tracked | L39: 2 | M39: new-muslim-guide — New Muslim Guide (New Muslim Guide) seekersguidance — SeekersGuidance (SeekersGuidance) | X39: https://www.revertguide.com/en/roadmap/month-1-2#stage-guidance-heading | Y39: month-1-2 | Z39: locales/en/stages.json › [id=month-1-2].focusNow | AA39: stage:month-1-2
A40: R0039 | B40: Roadmap stage | C40: Islam in daily life | D40: Can wait | E40: • Arguments about certification standards. • Detailed zakat and money rulings. • Clothing debates between different cultures. | F40: • প্রত্যয়নের মানদণ্ড নিয়ে তর্ক। • যাকাত আর টাকাপয়সার বিস্তারিত বিধান। • বিভিন্ন সংস্কৃতির মধ্যে পোশাক নিয়ে বিতর্ক। | G40: Translated | H40: Medium | I40: Financial (zakat, riba, money); External resource or teacher; Tone and pastoral wording | J40: Scholar; Mentor | K40: not tracked | L40: 2 | M40: new-muslim-guide — New Muslim Guide (New Muslim Guide) seekersguidance — SeekersGuidance (SeekersGuidance) | X40: https://www.revertguide.com/en/roadmap/month-1-2#stage-guidance-heading | Y40: month-1-2 | Z40: locales/en/stages.json › [id=month-1-2].canWait | AA40: stage:month-1-2
...

Sheet Items
A1: Item key | B1: Area | C1: Item | D1: Priority | E1: Review needed | F1: Suggested reviewer | G1: Current status (site) | H1: Key points to check | I1: Pre-check flags | J1: Sources (n) | K1: Sources used (id — title — link) | L1: Text rows | M1: Rows done | N1: Rows approved (EN) | O1: Rows approved (BN) | P1: Progress | Q1: Assigned reviewer(s) | R1: Item verdict | S1: Item notes | T1: Page URL | U1: JSON file
